Workbook
Name academicSessionList: AcademicSessions!$A$2:$A$6

Sheet 2026-27
A1: S.NO | B1: ProvisionalNumber | C1: ApplicantNumber | D1: StudentId | E1: AcademicSessionName | F1: AcademicSessionId | G1: ProgramName | H1: ProgramId | I1: OperationalVerticalName | J1: OperationalVerticalId | K1: DateOfAdmission | L1: StudentName | M1: DateOfBirth | N1: Gender | O1: EmailAddress | P1: PhoneNumber | Q1: AadharNumber | R1: Category | S1: BloodGroup | T1: Religion | U1: Nationality | V1: FatherName | W1: FatherMobileNumber | X1: FatherEmail | Y1: FatherOccupation | Z1: MotherName | AA1: MotherMobileNumber | AB1: Address1 | AC1: Address2 | AD1: City | AE1: State | AF1: MinimumQualification | AG1: LastBoardUniversity | AH1: ConcessionCategoryName | AI1: ConcessionCategoryId | AJ1: OVFCAmount | AK1: ConcessionUnit | AL1: ConcessionValue | AM1: ConcessionAmount | AN1: FeeAmount | AO1: PaidAmount | AP1: DueAmount | AQ1: IsAdmissionFeePaid | AR1: RegistrationFee | AS1: Password | AT1: RegistrationFeeTransactionId | AU1: IsWelcomeEmailSent | AV1: WelcomeEmailSentDate | AW1: Status
F2: =IFERROR(INDEX(AcademicSessions!$A$1:$A$100, MATCH(E2, AcademicSessions!$B$1:$B$100, 0)), "") | H2: =IFERROR(INDEX(Programs!$A$1:$A$100, MATCH(G2, Programs!$B$1:$B$100, 0)), "") | J2: =IFERROR(INDEX(Semesters!$A$1:$A$100, MATCH(I2, Semesters!$B$1:$B$100, 0)), "") | AI2: =IFERROR(INDEX(ConcessionCategory!$A$1:$A$100, MATCH(AH2, ConcessionCategory!$B$1:$B$100, 0)), "")
F3: =IFERROR(INDEX(AcademicSessions!$A$1:$A$100, MATCH(E3, AcademicSessions!$B$1:$B$100, 0)), "") | H3: =IFERROR(INDEX(Programs!$A$1:$A$100, MATCH(G3, Programs!$B$1:$B$100, 0)), "") | J3: =IFERROR(INDEX(Semesters!$A$1:$A$100, MATCH(I3, Semesters!$B$1:$B$100, 0)), "") | AI3: =IFERROR(INDEX(ConcessionCategory!$A$1:$A$100, MATCH(AH3, ConcessionCategory!$B$1:$B$100, 0)), "")
F4: =IFERROR(INDEX(AcademicSessions!$A$1:$A$100, MATCH(E4, AcademicSessions!$B$1:$B$100, 0)), "") | H4: =IFERROR(INDEX(Programs!$A$1:$A$100, MATCH(G4, Programs!$B$1:$B$100, 0)), "") | J4: =IFERROR(INDEX(Semesters!$A$1:$A$100, MATCH(I4, Semesters!$B$1:$B$100, 0)), "") | AI4: =IFERROR(INDEX(ConcessionCategory!$A$1:$A$100, MATCH(AH4, ConcessionCategory!$B$1:$B$100, 0)), "")
F5: =IFERROR(INDEX(AcademicSessions!$A$1:$A$100, MATCH(E5, AcademicSessions!$B$1:$B$100, 0)), "") | H5: =IFERROR(INDEX(Programs!$A$1:$A$100, MATCH(G5, Programs!$B$1:$B$100, 0)), "") | J5: =IFERROR(INDEX(Semesters!$A$1:$A$100, MATCH(I5, Semesters!$B$1:$B$100, 0)), "") | AI5: =IFERROR(INDEX(ConcessionCategory!$A$1:$A$100, MATCH(AH5, ConcessionCategory!$B$1:$B$100, 0)), "")
F6: =IFERROR(INDEX(AcademicSessions!$A$1:$A$100, MATCH(E6, AcademicSessions!$B$1:$B$100, 0)), "") | H6: =IFERROR(INDEX(Programs!$A$1:$A$100, MATCH(G6, Programs!$B$1:$B$100, 0)), "") | J6: =IFERROR(INDEX(Semesters!$A$1:$A$100, MATCH(I6, Semesters!$B$1:$B$100, 0)), "") | AI6: =IFERROR(INDEX(ConcessionCategory!$A$1:$A$100, MATCH(AH6, ConcessionCategory!$B$1:$B$100, 0)), "")
F7: =IFERROR(INDEX(AcademicSessions!$A$1:$A$100, MATCH(E7, AcademicSessions!$B$1:$B$100, 0)), "") | H7: =IFERROR(INDEX(Programs!$A$1:$A$100, MATCH(G7, Programs!$B$1:$B$100, 0)), "") | J7: =IFERROR(INDEX(Semesters!$A$1:$A$100, MATCH(I7, Semesters!$B$1:$B$100, 0)), "") | AI7: =IFERROR(INDEX(ConcessionCategory!$A$1:$A$100, MATCH(AH7, ConcessionCategory!$B$1:$B$100, 0)), "")
F8: =IFERROR(INDEX(AcademicSessions!$A$1:$A$100, MATCH(E8, AcademicSessions!$B$1:$B$100, 0)), "") | H8: =IFERROR(INDEX(Programs!$A$1:$A$100, MATCH(G8, Programs!$B$1:$B$100, 0)), "") | J8: =IFERROR(INDEX(Semesters!$A$1:$A$100, MATCH(I8, Semesters!$B$1:$B$100, 0)), "") | AI8: =IFERROR(INDEX(ConcessionCategory!$A$1:$A$100, MATCH(AH8, ConcessionCategory!$B$1:$B$100, 0)), "")
F9: =IFERROR(INDEX(AcademicSessions!$A$1:$A$100, MATCH(E9, AcademicSessions!$B$1:$B$100, 0)), "") | H9: =IFERROR(INDEX(Programs!$A$1:$A$100, MATCH(G9, Programs!$B$1:$B$100, 0)), "") | J9: =IFERROR(INDEX(Semesters!$A$1:$A$100, MATCH(I9, Semesters!$B$1:$B$100, 0)), "") | AI9: =IFERROR(INDEX(ConcessionCategory!$A$1:$A$100, MATCH(AH9, ConcessionCategory!$B$1:$B$100, 0)), "")
F10: =IFERROR(INDEX(AcademicSessions!$A$1:$A$100, MATCH(E10, AcademicSessions!$B$1:$B$100, 0)), "") | H10: =IFERROR(INDEX(Programs!$A$1:$A$100, MATCH(G10, Programs!$B$1:$B$100, 0)), "") | J10: =IFERROR(INDEX(Semesters!$A$1:$A$100, MATCH(I10, Semesters!$B$1:$B$100, 0)), "") | AI10: =IFERROR(INDEX(ConcessionCategory!$A$1:$A$100, MATCH(AH10, ConcessionCategory!$B$1:$B$100, 0)), "")
F11: =IFERROR(INDEX(AcademicSessions!$A$1:$A$100, MATCH(E11, AcademicSessions!$B$1:$B$100, 0)), "") | H11: =IFERROR(INDEX(Programs!$A$1:$A$100, MATCH(G11, Programs!$B$1:$B$100, 0)), "") | J11: =IFERROR(INDEX(Semesters!$A$1:$A$100, MATCH(I11, Semesters!$B$1:$B$100, 0)), "") | AI11: =IFERROR(INDEX(ConcessionCategory!$A$1:$A$100, MATCH(AH11, ConcessionCategory!$B$1:$B$100, 0)), "")
F12: =IFERROR(INDEX(AcademicSessions!$A$1:$A$100, MATCH(E12, AcademicSessions!$B$1:$B$100, 0)), "") | H12: =IFERROR(INDEX(Programs!$A$1:$A$100, MATCH(G12, Programs!$B$1:$B$100, 0)), "") | J12: =IFERROR(INDEX(Semesters!$A$1:$A$100, MATCH(I12, Semesters!$B$1:$B$100, 0)), "") | AI12: =IFERROR(INDEX(ConcessionCategory!$A$1:$A$100, MATCH(AH12, ConcessionCategory!$B$1:$B$100, 0)), "")
F13: =IFERROR(INDEX(AcademicSessions!$A$1:$A$100, MATCH(E13, AcademicSessions!$B$1:$B$100, 0)), "") | H13: =IFERROR(INDEX(Programs!$A$1:$A$100, MATCH(G13, Programs!$B$1:$B$100, 0)), "") | J13: =IFERROR(INDEX(Semesters!$A$1:$A$100, MATCH(I13, Semesters!$B$1:$B$100, 0)), "") | AI13: =IFERROR(INDEX(ConcessionCategory!$A$1:$A$100, MATCH(AH13, ConcessionCategory!$B$1:$B$100, 0)), "")
... F4533: =IFERROR(INDEX(AcademicSessions!$A$1:$A$100, MATCH(E4533, AcademicSessions!$B$1:$B$100, 0)), "") | H4533: =IFERROR(INDEX(Programs!$A$1:$A$100, MATCH(G4533, Programs!$B$1:$B$100, 0)), "") | J4533: =IFERROR(INDEX(Semesters!$A$1:$A$100, MATCH(I4533, Semesters!$B$1:$B$100, 0)), "") | AI4533: =IFERROR(INDEX(ConcessionCategory!$A$1:$A$100, MATCH(AH4533, ConcessionCategory!$B$1:$B$100, 0)), "")
F4534: =IFERROR(INDEX(AcademicSessions!$A$1:$A$100, MATCH(E4534, AcademicSessions!$B$1:$B$100, 0)), "") | H4534: =IFERROR(INDEX(Programs!$A$1:$A$100, MATCH(G4534, Programs!$B$1:$B$100, 0)), "") | AI4534: =IFERROR(INDEX(ConcessionCategory!$A$1:$A$100, MATCH(AH4534, ConcessionCategory!$B$1:$B$100, 0)), "")
F4535: =IFERROR(INDEX(AcademicSessions!$A$1:$A$100, MATCH(E4535, AcademicSessions!$B$1:$B$100, 0)), "") | H4535: =IFERROR(INDEX(Programs!$A$1:$A$100, MATCH(G4535, Programs!$B$1:$B$100, 0)), "") | AI4535: =IFERROR(INDEX(ConcessionCategory!$A$1:$A$100, MATCH(AH4535, ConcessionCategory!$B$1:$B$100, 0)), "")
F4536: =IFERROR(INDEX(AcademicSessions!$A$1:$A$100, MATCH(E4536, AcademicSessions!$B$1:$B$100, 0)), "") | H4536: =IFERROR(INDEX(Programs!$A$1:$A$100, MATCH(G4536, Programs!$B$1:$B$100, 0)), "") | AI4536: =IFERROR(INDEX(ConcessionCategory!$A$1:$A$100, MATCH(AH4536, ConcessionCategory!$B$1:$B$100, 0)), "")
F4537: =IFERROR(INDEX(AcademicSessions!$A$1:$A$100, MATCH(E4537, AcademicSessions!$B$1:$B$100, 0)), "") | H4537: =IFERROR(INDEX(Programs!$A$1:$A$100, MATCH(G4537, Programs!$B$1:$B$100, 0)), "") | AI4537: =IFERROR(INDEX(ConcessionCategory!$A$1:$A$100, MATCH(AH4537, ConcessionCategory!$B$1:$B$100, 0)), "")
F4538: =IFERROR(INDEX(AcademicSessions!$A$1:$A$100, MATCH(E4538, AcademicSessions!$B$1:$B$100, 0)), "") | H4538: =IFERROR(INDEX(Programs!$A$1:$A$100, MATCH(G4538, Programs!$B$1:$B$100, 0)), "") | AI4538: =IFERROR(INDEX(ConcessionCategory!$A$1:$A$100, MATCH(AH4538, ConcessionCategory!$B$1:$B$100, 0)), "")
F4539: =IFERROR(INDEX(AcademicSessions!$A$1:$A$100, MATCH(E4539, AcademicSessions!$B$1:$B$100, 0)), "") | H4539: =IFERROR(INDEX(Programs!$A$1:$A$100, MATCH(G4539, Programs!$B$1:$B$100, 0)), "") | AI4539: =IFERROR(INDEX(ConcessionCategory!$A$1:$A$100, MATCH(AH4539, ConcessionCategory!$B$1:$B$100, 0)), "")
H4540: =IFERROR(INDEX(Programs!$A$1:$A$100, MATCH(G4540, Programs!$B$1:$B$100, 0)), "") | AI4540: =IFERROR(INDEX(ConcessionCategory!$A$1:$A$100, MATCH(AH4540, ConcessionCategory!$B$1:$B$100, 0)), "")
H4541: =IFERROR(INDEX(Programs!$A$1:$A$100, MATCH(G4541, Programs!$B$1:$B$100, 0)), "") | AI4541: =IFERROR(INDEX(ConcessionCategory!$A$1:$A$100, MATCH(AH4541, ConcessionCategory!$B$1:$B$100, 0)), "")
H4542: =IFERROR(INDEX(Programs!$A$1:$A$100, MATCH(G4542, Programs!$B$1:$B$100, 0)), "") | AI4542: =IFERROR(INDEX(ConcessionCategory!$A$1:$A$100, MATCH(AH4542, ConcessionCategory!$B$1:$B$100, 0)), "")
H4543: =IFERROR(INDEX(Programs!$A$1:$A$100, MATCH(G4543, Programs!$B$1:$B$100, 0)), "") | AI4543: =IFERROR(INDEX(ConcessionCategory!$A$1:$A$100, MATCH(AH4543, ConcessionCategory!$B$1:$B$100, 0)), "")
H4544: =IFERROR(INDEX(Programs!$A$1:$A$100, MATCH(G4544, Programs!$B$1:$B$100, 0)), "") | AI4544: =IFERROR(INDEX(ConcessionCategory!$A$1:$A$100, MATCH(AH4544, ConcessionCategory!$B$1:$B$100, 0)), "")
H4545: =IFERROR(INDEX(Programs!$A$1:$A$100, MATCH(G4545, Programs!$B$1:$B$100, 0)), "") | AI4545: =IFERROR(INDEX(ConcessionCategory!$A$1:$A$100, MATCH(AH4545, ConcessionCategory!$B$1:$B$100, 0)), "")
H4546: =IFERROR(INDEX(Programs!$A$1:$A$100, MATCH(G4546, Programs!$B$1:$B$100, 0)), "") | AI4546: =IFERROR(INDEX(ConcessionCategory!$A$1:$A$100, MATCH(AH4546, ConcessionCategory!$B$1:$B$100, 0)), "")
H4547: =IFERROR(INDEX(Programs!$A$1:$A$100, MATCH(G4547, Programs!$B$1:$B$100, 0)), "") | AI4547: =IFERROR(INDEX(ConcessionCategory!$A$1:$A$100, MATCH(AH4547, ConcessionCategory!$B$1:$B$100, 0)), "")
H4548: =IFERROR(INDEX(Programs!$A$1:$A$100, MATCH(G4548, Programs!$B$1:$B$100, 0)), "") | AI4548: =IFERROR(INDEX(ConcessionCategory!$A$1:$A$100, MATCH(AH4548, ConcessionCategory!$B$1:$B$100, 0)), "")
H4549: =IFERROR(INDEX(Programs!$A$1:$A$100, MATCH(G4549, Programs!$B$1:$B$100, 0)), "") | AI4549: =IFERROR(INDEX(ConcessionCategory!$A$1:$A$100, MATCH(AH4549, ConcessionCategory!$B$1:$B$100, 0)), "")
H4550: =IFERROR(INDEX(Programs!$A$1:$A$100, MATCH(G4550, Programs!$B$1:$B$100, 0)), "") | AI4550: =IFERROR(INDEX(ConcessionCategory!$A$1:$A$100, MATCH(AH4550, ConcessionCategory!$B$1:$B$100, 0)), "")
H4551: =IFERROR(INDEX(Programs!$A$1:$A$100, MATCH(G4551, Programs!$B$1:$B$100, 0)), "") | AI4551: =IFERROR(INDEX(ConcessionCategory!$A$1:$A$100, MATCH(AH4551, ConcessionCategory!$B$1:$B$100, 0)), "")
... H4636: =IFERROR(INDEX(Programs!$A$1:$A$100, MATCH(G4636, Programs!$B$1:$B$100, 0)), "") | AI4636: =IFERROR(INDEX(ConcessionCategory!$A$1:$A$100, MATCH(AH4636, ConcessionCategory!$B$1:$B$100, 0)), "")
AI4637: =IFERROR(INDEX(ConcessionCategory!$A$1:$A$100, MATCH(AH4637, ConcessionCategory!$B$1:$B$100, 0)), "")
AI4638: =IFERROR(INDEX(ConcessionCategory!$A$1:$A$100, MATCH(AH4638, ConcessionCategory!$B$1:$B$100, 0)), "")
AI4639: =IFERROR(INDEX(ConcessionCategory!$A$1:$A$100, MATCH(AH4639, ConcessionCategory!$B$1:$B$100, 0)), "")
AI4640: =IFERROR(INDEX(ConcessionCategory!$A$1:$A$100, MATCH(AH4640, ConcessionCategory!$B$1:$B$100, 0)), "")
AI4641: =IFERROR(INDEX(ConcessionCategory!$A$1:$A$100, MATCH(AH4641, ConcessionCategory!$B$1:$B$100, 0)), "")
AI4642: =IFERROR(INDEX(ConcessionCategory!$A$1:$A$100, MATCH(AH4642, ConcessionCategory!$B$1:$B$100, 0)), "")
AI4643: =IFERROR(INDEX(ConcessionCategory!$A$1:$A$100, MATCH(AH4643, ConcessionCategory!$B$1:$B$100, 0)), "")
...

Sheet AcademicSessions
A1: Id | B1: Name
A2: 36 | B2: 2026-2029
A3: 37 | B3: 2026-2027
A4: 38 | B4: 2026-2028
A5: 39 | B5: 2026-2030
A6: 40 | B6: 2026-2031

Sheet Programs
A1: Id | B1: Name
A2: 1 | B2: Bachelor of Technology in Computer Science & Engineering
A3: 2 | B3: Bachelor of Technology in Civil Engineering
A4: 3 | B4: Bachelor of Computer Applications
A5: 4 | B5: Bachelor of Technology in Electrical & Electronics Engineering
A6: 5 | B6: Bachelor of Technology in Electronics & Communication Engineering
A7: 6 | B7: Bachelor of Technology in Mechanical Engineering
A8: 7 | B8: Diploma in Computer Science & Engineering
A9: 8 | B9: Diploma in Civil Engineering
A10: 9 | B10: Diploma in Mechanical Engineering
A11: 10 | B11: Diploma in Electrical & Electronics Engineering
A12: 11 | B12: Diploma in Electronics & Communication Engineering
A13: 12 | B13: Master of Computer Applications
... A85: 86 | B85: Doctor of Philosophy in Pharmacy

Sheet Semesters
A1: Id | B1: Name
A2: 1 | B2: SEMESTER I
A3: 2 | B3: SEMESTER II
A4: 3 | B4: SEMESTER III
A5: 4 | B5: SEMESTER IV
A6: 5 | B6: SEMESTER V
A7: 6 | B7: SEMESTER VI
A8: 7 | B8: SEMESTER VII
A9: 8 | B9: SEMESTER VIII
A10: 9 | B10: SEMESTER IX
A11: 10 | B11: SEMESTER X

Sheet ConcessionCategory
A1: Id | B1: Name
A2: 1 | B2: BAGM UNITS 25%
A3: 2 | B3: Special Scholarship
A4: 3 | B4: B .Tech Merit Scholarship 25% on 70% Marks
A5: 4 | B5: SBPS Student 25%
A6: 5 | B6: Armed Forces 15%
A7: 6 | B7: Sports
A8: 7 | B8: B. Tech Merit Scholarship 50% on 80% Marks
A9: 8 | B9: B. Tech Merit Scholarship100% on 90% Marks
A10: 9 | B10: JAC & Bihar Board Scholarship 10% on 60% Marks
A11: 10 | B11: JAC & Bihar Board Scholarship 20% on 70% Marks
A12: 11 | B12: JAC & Bihar Board Scholarship 50% on 80% Marks
A13: 12 | B13: JAC & Bihar Board Scholarship 100% on 90% Marks
... A44: 44 | B44: Merit Scholarship 10%
